---
linkTitle: "4.2.1 Throwing and Catching Exceptions"
title: "Mastering Exception Handling in Clojure: Throwing and Catching Exceptions"
description: "Explore advanced techniques for throwing and catching exceptions in Clojure, including defining custom exception types and leveraging try-catch-finally blocks for robust error management."
categories:
- Clojure Programming
- Functional Programming
- Error Handling
tags:
- Clojure
- Exception Handling
- Functional Programming
- Error Management
- Java Interoperability
date: 2024-10-25
type: docs
nav_weight: 421000
canonical: "https://clojureforjava.com/2/4/2/1"
license: "Â© 2024 Tokenizer Inc. CC BY-NC-SA 4.0"
---

## 4.2.1 Throwing and Catching Exceptions

In the realm of software development, handling errors gracefully is a critical aspect of building robust applications. For Java engineers transitioning to Clojure, understanding how to effectively manage exceptions is essential. While Clojure, as a functional programming language, encourages a paradigm shift away from exception-heavy error handling, there are scenarios where exceptions are unavoidable. This section delves into the intricacies of throwing and catching exceptions in Clojure, providing you with the knowledge to handle errors efficiently while maintaining the functional programming ethos.

### Throwing Exceptions in Clojure

In Clojure, exceptions are thrown using the `throw` function, which is analogous to Java's `throw` statement. The `throw` function requires an instance of `java.lang.Throwable` or any of its subclasses. This means you can throw standard Java exceptions or define your own custom exceptions.

#### Basic Exception Throwing

Here's a simple example of throwing a standard Java exception in Clojure:

```clojure
(defn divide [numerator denominator]
  (if (zero? denominator)
    (throw (IllegalArgumentException. "Denominator cannot be zero"))
    (/ numerator denominator)))

;; Usage
(try
  (println (divide 10 0))
  (catch IllegalArgumentException e
    (println "Caught exception:" (.getMessage e))))
```

In this example, the `divide` function checks if the denominator is zero and throws an `IllegalArgumentException` if true. The `try-catch` block is used to catch and handle the exception.

#### Defining Custom Exception Types

Defining custom exceptions in Clojure is straightforward, leveraging Java's class system. You can create a new exception type by extending `java.lang.Exception` or any other appropriate superclass.

```clojure
(defrecord CustomException [message]
  Exception
  (getMessage [this] message))

(defn risky-operation []
  (throw (->CustomException "Something went wrong")))

;; Usage
(try
  (risky-operation)
  (catch CustomException e
    (println "Caught custom exception:" (.getMessage e))))
```

In this example, `CustomException` is defined using `defrecord`, which allows for the creation of a new exception type with a custom message.

### Catching Exceptions with try-catch-finally

Clojure provides the `try`, `catch`, and `finally` constructs for handling exceptions, similar to Java. These constructs allow you to manage exceptions and perform cleanup operations.

#### Basic try-catch Example

The `try-catch` block is used to catch exceptions and execute specific code when an exception occurs.

```clojure
(defn safe-divide [numerator denominator]
  (try
    (/ numerator denominator)
    (catch ArithmeticException e
      (println "Arithmetic error:" (.getMessage e))
      nil)))

;; Usage
(safe-divide 10 0) ;; Output: Arithmetic error: Divide by zero
```

In this example, the `safe-divide` function attempts to divide two numbers and catches any `ArithmeticException`, printing an error message and returning `nil`.

#### Using finally for Cleanup

The `finally` block is executed regardless of whether an exception is thrown, making it ideal for cleanup operations.

```clojure
(defn read-file [filename]
  (let [reader (java.io.BufferedReader. (java.io.FileReader. filename))]
    (try
      (loop [line (.readLine reader)]
        (when line
          (println line)
          (recur (.readLine reader))))
      (catch java.io.IOException e
        (println "IO error:" (.getMessage e)))
      (finally
        (.close reader)))))

;; Usage
(read-file "example.txt")
```

In this example, the `finally` block ensures that the file reader is closed, preventing resource leaks.

### Exception Handling in Various Scenarios

Let's explore some practical scenarios where exception handling is crucial in Clojure applications.

#### Network Operations

Network operations are prone to errors such as timeouts and unreachable hosts. Proper exception handling ensures that your application can recover gracefully from such errors.

```clojure
(defn fetch-url [url]
  (try
    (let [response (slurp url)]
      (println "Response received:" response))
    (catch java.net.MalformedURLException e
      (println "Invalid URL:" (.getMessage e)))
    (catch java.io.IOException e
      (println "Network error:" (.getMessage e)))))
```

In this example, the `fetch-url` function attempts to read from a URL and handles both malformed URLs and IO exceptions.

#### Database Operations

Database interactions often involve exceptions related to connectivity and data integrity. Handling these exceptions is vital for maintaining data consistency.

```clojure
(defn query-database [query]
  (try
    ;; Simulate database query
    (if (= query "SELECT * FROM non_existent_table")
      (throw (SQLException. "Table does not exist"))
      (println "Query successful"))
    (catch SQLException e
      (println "Database error:" (.getMessage e)))))
```

Here, the `query-database` function simulates a database query and handles `SQLException` to manage database-related errors.

### Best Practices and Functional Approaches

While exceptions are a powerful tool for error handling, overusing them can lead to code that is difficult to maintain and understand. Clojure encourages more functional approaches to error management, such as using `Either` and `Maybe` monads, or leveraging validation libraries like `Schema` and `Spec`.

#### Avoiding Overuse of Exceptions

- **Use Exceptions for Exceptional Cases:** Reserve exceptions for truly exceptional conditions that cannot be handled through normal control flow.
- **Prefer Functional Error Handling:** Consider using functional constructs like `Either` or `Maybe` to represent computations that may fail, allowing for more predictable error handling.

#### Example: Functional Error Handling

```clojure
(defn divide-safe [numerator denominator]
  (if (zero? denominator)
    {:error "Denominator cannot be zero"}
    {:result (/ numerator denominator)}))

;; Usage
(let [result (divide-safe 10 0)]
  (if (:error result)
    (println "Error:" (:error result))
    (println "Result:" (:result result))))
```

In this example, the `divide-safe` function returns a map with either a `:result` or `:error` key, allowing the caller to handle errors functionally.

### Conclusion

Exception handling in Clojure, while similar to Java in syntax, requires a shift in mindset to embrace functional programming principles. By understanding how to throw and catch exceptions effectively, and when to opt for more functional approaches, you can build robust, maintainable Clojure applications. Remember to use exceptions judiciously and explore functional error handling techniques to align with Clojure's philosophy.

## Quiz Time!

{{< quizdown >}}

### What function is used to throw exceptions in Clojure?

- [x] `throw`
- [ ] `raise`
- [ ] `error`
- [ ] `exception`

> **Explanation:** In Clojure, the `throw` function is used to throw exceptions, similar to Java's `throw` statement.

### How do you define a custom exception type in Clojure?

- [x] By using `defrecord` to extend `Exception`
- [ ] By using `defclass`
- [ ] By using `defexception`
- [ ] By using `defmacro`

> **Explanation:** Custom exception types in Clojure can be defined using `defrecord` to extend `Exception` or any other appropriate superclass.

### Which block is used for cleanup operations in Clojure's exception handling?

- [x] `finally`
- [ ] `catch`
- [ ] `try`
- [ ] `cleanup`

> **Explanation:** The `finally` block is used for cleanup operations and is executed regardless of whether an exception is thrown.

### What is the purpose of the `catch` block in Clojure?

- [x] To handle exceptions
- [ ] To throw exceptions
- [ ] To define exceptions
- [ ] To log exceptions

> **Explanation:** The `catch` block is used to handle exceptions that occur within the `try` block.

### Which of the following is a best practice regarding exception usage in Clojure?

- [x] Use exceptions for truly exceptional cases
- [ ] Use exceptions for all error handling
- [ ] Avoid using exceptions entirely
- [ ] Use exceptions only for input validation

> **Explanation:** Exceptions should be reserved for truly exceptional conditions that cannot be handled through normal control flow.

### What is a functional alternative to using exceptions for error handling in Clojure?

- [x] Using `Either` or `Maybe` monads
- [ ] Using `try-catch` blocks
- [ ] Using `throw` statements
- [ ] Using `finally` blocks

> **Explanation:** Functional constructs like `Either` or `Maybe` monads can be used to represent computations that may fail, providing a more predictable way to handle errors.

### How can you handle multiple types of exceptions in a single `try` block?

- [x] By using multiple `catch` clauses
- [ ] By using a single `catch` clause
- [ ] By using a `finally` clause
- [ ] By using nested `try` blocks

> **Explanation:** Multiple `catch` clauses can be used to handle different types of exceptions within a single `try` block.

### What is the output of the following code snippet?

```clojure
(try
  (/ 10 0)
  (catch ArithmeticException e
    (println "Arithmetic error:" (.getMessage e))))
```

- [x] Arithmetic error: Divide by zero
- [ ] Arithmetic error: Division by zero
- [ ] Arithmetic error: Zero division
- [ ] No output

> **Explanation:** The code attempts to divide by zero, which throws an `ArithmeticException`, and the `catch` block prints the error message.

### In Clojure, which construct is used to ensure a resource is closed after use?

- [x] `finally`
- [ ] `catch`
- [ ] `try`
- [ ] `close`

> **Explanation:** The `finally` block is used to ensure that resources are closed after use, regardless of whether an exception is thrown.

### True or False: Clojure encourages the use of exceptions for all error handling.

- [ ] True
- [x] False

> **Explanation:** False. Clojure encourages more functional approaches to error handling, such as using `Either` and `Maybe` monads, rather than relying heavily on exceptions.

{{< /quizdown >}}
